<?xml version="1.0" ?>
<robot name="humanoid">

    <link name="torso">
        <visual>
            <geometry>
                <cylinder length="0.04" radius="0.01"/>
            </geometry>
            <origin xyz="0 0 0.02" rpy="0 1.57 0"/>
            <axis xyz="0 0 0" />
            <material name="red">
                <color rgba="1 0.0 0.0 1.0"/>
            </material>
        </visual>
        <inertial>
            <mass value="0"/>
            <inertia ixx="0" ixy="0" ixz="0.0" iyy="0" iyz="0.0" izz="0"/>
        </inertial>
    </link>


    <!-- ****************************Right leg joints******************************************** -->

    <joint name="jointHipR" type="revolute">
        <parent link="torso"/>
        <child link="hipCylinderR"/>
        <origin xyz="0 0.0 0.0" rpy="0 0 0"/>
        <axis xyz="1 0 0"/>
        <limit effort="10" lower="-3" upper="+3" velocity="10"/>
        <dynamics damping="0"/>
    </joint>


    <link name="hipCylinderR">
        <visual>
            <geometry>
                <cylinder length="0.04" radius="0.01"/>
            </geometry>
            <origin xyz="0 0 0.02" rpy="0 1.57 0"/>
            <axis xyz="0 0 0" />
            <material name="red">
                <color rgba="1 0.0 0.0 1.0"/>
            </material>
        </visual>
        <inertial>
            <mass value="0"/>
            <inertia ixx="0" ixy="0" ixz="0.0" iyy="0" iyz="0.0" izz="0"/>
        </inertial>
    </link>

    <joint name="jointUpperLegR" type="revolute">
        <parent link="hipCylinderR"/>
        <child link="upperLegCylinderR"/>
        <origin xyz="0 -0.0830 -0.0250" rpy="0 0 0"/>
        <axis xyz="0 1 0"/>
        <limit effort="10" lower="-3" upper="+3" velocity="10"/>
        <dynamics damping="0"/>
    </joint>

    <link name="upperLegCylinderR">
        <visual>
            <geometry>
                <cylinder length="0.04" radius="0.01"/>
            </geometry>
            <origin xyz="0 0 0.02" rpy="1.57 0 0"/>
            <axis xyz="0 0 0" />
            <material name="red"/>
        </visual>
        <inertial>
            <mass value="0"/>
            <inertia ixx="0" ixy="0" ixz="0.0" iyy="0" iyz="0.0" izz="0"/>
        </inertial>
    </link>

    <joint name="jointLowerLegR" type="revolute">
        <parent link="upperLegCylinderR"/>
        <child link="lowerlegCylinderR"/>
        <origin xyz="0.00110 0.0140 -0.3155" rpy="0 0 0"/>
        <axis xyz="0 1 0"/>
        <limit effort="10" lower="-3" upper="+3" velocity="10"/>
        <dynamics damping="0"/>
    </joint>

    <link name="lowerlegCylinderR">
        <visual>
            <geometry>
                <cylinder length="0.044" radius="0.01"/>
            </geometry>
            <origin xyz="0 0 0" rpy="1.57075 0 0"/>
            <axis xyz="0 0 0" />
            <material name="red"/>
        </visual>
        <inertial>
            <mass value="0"/>
            <inertia ixx="0" ixy="0" ixz="0.0" iyy="0" iyz="0.0" izz="0"/>
        </inertial>
    </link>

    <joint name="jointAnkleR" type="revolute">
        <parent link="lowerlegCylinderR"/>
        <child link="ankleCylinderR"/>
        <origin xyz="0.00300 0 -0.28" rpy="0 0 0"/>
        <axis xyz="0 1 0"/>
        <limit effort="10" lower="-3" upper="+3" velocity="10"/>
        <dynamics damping="0"/>
    </joint>

    <link name="ankleCylinderR">
        <visual>
            <geometry>
                <cylinder length="0.04" radius="0.01"/>
            </geometry>
            <origin xyz="0 0 0.02" rpy="1.57075 0 0"/>
            <axis xyz="0 0 0" />
            <material name="red"/>
        </visual>
        <inertial>
            <mass value="0"/>
            <inertia ixx="0" ixy="0" ixz="0.0" iyy="0" iyz="0.0" izz="0"/>
        </inertial>
    </link>

    <joint name="jointfootR" type="revolute">
        <parent link="ankleCylinderR"/>
        <child link="footCylinderR"/>
        <origin xyz="0 0 -0.0115" rpy="0 0 0"/>
        <axis xyz="1 0 0"/>
        <limit effort="10" lower="-3" upper="+3" velocity="10"/>
        <dynamics damping="0"/>
    </joint>

    <link name="footCylinderR">
        <visual>
            <geometry>
                <cylinder length="0.04" radius="0.01"/>
            </geometry>
            <origin xyz="0 0 0.02" rpy="0 1.57 0"/>
            <axis xyz="0 0 0" />
            <material name="red"/>
        </visual>
        <inertial>
            <mass value="0"/>
            <inertia ixx="0" ixy="0" ixz="0.0" iyy="0" iyz="0.0" izz="0"/>
        </inertial>
    </link>


    <!--************************************ Left leg joints **********************************************-->


    <joint name="jointHipL" type="revolute">
        <parent link="torso"/>
        <child link="hipCylinderL"/>
        <origin xyz="0 0.0 0.0" rpy="0 0 0"/>
        <axis xyz="1 0 0"/>
        <limit effort="10" lower="-3" upper="+3" velocity="10"/>
        <dynamics damping="0"/>
    </joint>


    <link name="hipCylinderL">
        <visual>
            <geometry>
                <cylinder length="0.04" radius="0.01"/>
            </geometry>
            <origin xyz="0 0 0.02" rpy="0 1.57 0"/>
            <axis xyz="0 0 0" />
            <material name="red">
                <color rgba="1 0.0 0.0 1.0"/>
            </material>
        </visual>
        <inertial>
            <mass value="0"/>
            <inertia ixx="0" ixy="0" ixz="0.0" iyy="0" iyz="0.0" izz="0"/>
        </inertial>
    </link>

    <joint name="jointUpperLegL" type="revolute">
        <parent link="hipCylinderL"/>
        <child link="upperLegCylinderL"/>
        <origin xyz="0 0.0830 -0.0250" rpy="0 0 0"/>
        <axis xyz="0 1 0"/>
        <limit effort="10" lower="-3" upper="+3" velocity="10"/>
        <dynamics damping="0"/>
    </joint>

    <link name="upperLegCylinderL">
        <visual>
            <geometry>
                <cylinder length="0.04" radius="0.01"/>
            </geometry>
            <origin xyz="0 0 0.02" rpy="1.57 0 0"/>
            <axis xyz="0 0 0" />
            <material name="red"/>
        </visual>
        <inertial>
            <mass value="0"/>
            <inertia ixx="0" ixy="0" ixz="0.0" iyy="0" iyz="0.0" izz="0"/>
        </inertial>
    </link>

    <joint name="jointLowerLegL" type="revolute">
        <parent link="upperLegCylinderL"/>
        <child link="lowerlegCylinderL"/>
        <origin xyz="0.00110 -0.0140 -0.3155" rpy="0 0 0"/>
        <axis xyz="0 1 0"/>
        <limit effort="10" lower="-3" upper="+3" velocity="10"/>
        <dynamics damping="0"/>
    </joint>

    <link name="lowerlegCylinderL">
        <visual>
            <geometry>
                <cylinder length="0.044" radius="0.01"/>
            </geometry>
            <origin xyz="0 0 0" rpy="1.57075 0 0"/>
            <axis xyz="0 0 0" />
            <material name="red"/>
        </visual>
        <inertial>
            <mass value="0"/>
            <inertia ixx="0" ixy="0" ixz="0.0" iyy="0" iyz="0.0" izz="0"/>
        </inertial>
    </link>

    <joint name="jointAnkleL" type="revolute">
        <parent link="lowerlegCylinderL"/>
        <child link="ankleCylinderL"/>
        <origin xyz="0.00300 0 -0.28" rpy="0 0 0"/>
        <axis xyz="0 1 0"/>
        <limit effort="10" lower="-3" upper="+3" velocity="10"/>
        <dynamics damping="0"/>
    </joint>

    <link name="ankleCylinderL">
        <visual>
            <geometry>
                <cylinder length="0.04" radius="0.01"/>
            </geometry>
            <origin xyz="0 0 0.02" rpy="1.57075 0 0"/>
            <axis xyz="0 0 0" />
            <material name="red"/>
        </visual>
        <inertial>
            <mass value="0"/>
            <inertia ixx="0" ixy="0" ixz="0.0" iyy="0" iyz="0.0" izz="0"/>
        </inertial>
    </link>

    <joint name="jointfootL" type="revolute">
        <parent link="ankleCylinderL"/>
        <child link="footCylinderL"/>
        <origin xyz="0 0 -0.0115" rpy="0 0 0"/>
        <axis xyz="1 0 0"/>
        <limit effort="10" lower="-3" upper="+3" velocity="10"/>
        <dynamics damping="0"/>
    </joint>

    <link name="footCylinderL">
        <visual>
            <geometry>
                <cylinder length="0.04" radius="0.01"/>
            </geometry>
            <origin xyz="0 0 0.02" rpy="0 1.57 0"/>
            <axis xyz="0 0 0" />
            <material name="red"/>
        </visual>
        <inertial>
            <mass value="0"/>
            <inertia ixx="0" ixy="0" ixz="0.0" iyy="0" iyz="0.0" izz="0"/>
        </inertial>
    </link>




    <!-- **************************************Decorations Right leg **********************************************-->


    <joint name="fixed_hipBridgeR" type="fixed">
        <parent link="hipCylinderR"/>
        <child link="hipBridgeR"/>
    </joint>

    <link name="hipBridgeR">
        <visual>
            <geometry>
                <box size="0.02 0.0830 0.0250"/>
            </geometry>
            <origin xyz="-0.01 -0.0415 0.0125" rpy="0 0 0"/>
            <material name="linkColor">
                <color rgba="1 1 1 1"/>
            </material>
        </visual>
        <inertial>
            <mass value="0.219"/>
            <inertia ixx="414" ixy="0.149" ixz="0.00188" iyy="0.128" iyz="-0.0311" izz="0.359"/>
            <origin rpy="0 0 0" xyz="0.00131 -0.0515 -0.00661"/>
        </inertial>
        <collision>
            <geometry>
                <box size="0.02 0.0830 0.0250"/>
            </geometry>
            <origin xyz="-0.01 -0.415 0.0125" rpy="0 0 0"/>
        </collision>
    </link>

    <joint name="fixed_upperLegBridgeR" type="fixed">
        <parent link="upperLegCylinderR"/>
        <child link="upperLegBridgeR"/>
    </joint>

    <link name="upperLegBridgeR">
        <visual>
            <geometry>
                <box size="0.1 0.05 0.3155"/>
            </geometry>
            <origin xyz="-0.05 0 -0.15" rpy="0 0 0"/>
            <material name="linkColor">
                <color rgba="1 1 1 1"/>
            </material>
        </visual>
        <inertial>
            <mass value="1.94"/>
            <inertia ixx="10.4" ixy="-0.00195" ixz="0.0231" iyy="9.33" iyz="-0.127" izz="1.61"/>
            <origin xyz="-0.00154  -0.00421 -0.111" rpy="0 0 0"/>
        </inertial>
        <collision>
            <geometry>
                <box size="0.1 0.05 0.3155"/>
            </geometry>
            <origin xyz="-0.05 0 -0.15" rpy="0 0 0"/>
        </collision>
    </link>

    <joint name="fixed_lowerLegBridgeR" type="fixed">
        <parent link="lowerlegCylinderR"/>
        <child link="lowerLegBridgeR"/>
    </joint>

    <link name="lowerLegBridgeR">
        <visual>
            <geometry>
                <box size="0.1 0.05 0.28"/>
            </geometry>
            <origin xyz="-0.05 0 -0.14" rpy="0 0 0"/>
            <material name="linkColor">
                <color rgba="1 1 1 1"/>
            </material>
        </visual>
        <inertial>
            <mass value="0.267"/>
            <inertia ixx="2.52" ixy="-0.000411" ixz="-0.0238" iyy="2.45" iyz="0.0366" izz="0.110"/>
            <origin xyz="0.00135  0.00496 -0.105" rpy="0 0 0"/>
        </inertial>
        <collision>
            <geometry>
                <box size="0.1 0.05 0.28"/>
            </geometry>
            <origin xyz="-0.05 0 -0.14" rpy="0 0 0"/>
        </collision>
    </link>


    <joint name="fixed_ankleBridgeR" type="fixed">
        <parent link="ankleCylinderR"/>
        <child link="ankleBridgeR"/>
    </joint>

    <link name="ankleBridgeR">
        <visual>
            <geometry>
                <box size="0.1 0.05 0.02"/>
            </geometry>
            <origin xyz="0.05 0 -0.01" rpy="0 0 0"/>
            <material name="linkColor">
                <color rgba="1 1 1 1"/>
            </material>
        </visual>
        <inertial>
            <mass value="0.2356"/>
            <inertia ixx="0.0952" ixy="0.00066457" ixz="0.0003989" iyy="0.5002" iyz="-0.005328" izz="0.5679"/>
            <origin xyz="0.0230654545  0.0004316655 -0.0061157216" rpy="0 0 0"/>
        </inertial>
        <collision>
            <geometry>
                <box size="0.1 0.05 0.02"/>
            </geometry>
            <origin xyz="0.05 0 -0.01" rpy="0 0 0"/>
        </collision>
    </link>


    <!--&lt;!&ndash; *********************************Decorations Left leg ******************************************&ndash;&gt;-->
    <joint name="fixed_hipBridgeL" type="fixed">
        <parent link="hipCylinderL"/>
        <child link="hipBridgeL"/>
    </joint>

    <link name="hipBridgeL">
        <visual>
            <geometry>
                <box size="0.02 0.0830 0.0250"/>
            </geometry>
            <origin xyz="-0.01 0.0415 0.0125" rpy="0 0 0"/>
            <material name="linkColor">
                <color rgba="1 1 1 1"/>
            </material>
        </visual>
        <inertial>
            <mass value="0.219"/>
            <inertia ixx="414" ixy="0.149" ixz="0.00188" iyy="0.128" iyz="-0.0311" izz="0.359"/>
            <origin rpy="0 0 0" xyz="0.00131 -0.0515 -0.00661"/>
        </inertial>
        <collision>
            <geometry>
                <box size="0.02 0.0830 0.0250"/>
            </geometry>
            <origin xyz="-0.01 0.415 0.0125" rpy="0 0 0"/>
        </collision>
    </link>

    <joint name="fixed_upperLegBridgeL" type="fixed">
        <parent link="upperLegCylinderL"/>
        <child link="upperLegBridgeL"/>
    </joint>

    <link name="upperLegBridgeL">
        <visual>
            <geometry>
                <box size="0.1 0.05 0.3155"/>
            </geometry>
            <origin xyz="-0.05 0 -0.15" rpy="0 0 0"/>
            <material name="linkColor">
                <color rgba="1 1 1 1"/>
            </material>
        </visual>
        <inertial>
            <mass value="1.94"/>
            <inertia ixx="10.4" ixy="-0.00195" ixz="0.0231" iyy="9.33" iyz="-0.127" izz="1.61"/>
            <origin xyz="-0.00154  -0.00421 -0.111" rpy="0 0 0"/>
        </inertial>
        <collision>
            <geometry>
                <box size="0.1 0.05 0.3155"/>
            </geometry>
            <origin xyz="-0.05 0 -0.15" rpy="0 0 0"/>
        </collision>
    </link>

    <joint name="fixed_lowerLegBridgeL" type="fixed">
        <parent link="lowerlegCylinderL"/>
        <child link="lowerLegBridgeL"/>
    </joint>

    <link name="lowerLegBridgeL">
        <visual>
            <geometry>
                <box size="0.1 0.05 0.28"/>
            </geometry>
            <origin xyz="-0.05 0 -0.14" rpy="0 0 0"/>
            <material name="linkColor">
                <color rgba="1 1 1 1"/>
            </material>
        </visual>
        <inertial>
            <mass value="0.267"/>
            <inertia ixx="2.52" ixy="-0.000411" ixz="-0.0238" iyy="2.45" iyz="0.0366" izz="0.110"/>
            <origin xyz="0.00135  0.00496 -0.105" rpy="0 0 0"/>
        </inertial>
        <collision>
            <geometry>
                <box size="0.1 0.05 0.28"/>
            </geometry>
            <origin xyz="-0.05 0 -0.14" rpy="0 0 0"/>
        </collision>
    </link>


    <joint name="fixed_ankleBridgeL" type="fixed">
        <parent link="ankleCylinderL"/>
        <child link="ankleBridgeL"/>
    </joint>

    <link name="ankleBridgeL">
        <visual>
            <geometry>
                <box size="0.1 0.05 0.02"/>
            </geometry>
            <origin xyz="0.05 0 -0.01" rpy="0 0 0"/>
            <material name="linkColor">
                <color rgba="1 1 1 1"/>
            </material>
        </visual>
        <inertial>
            <mass value="0.2356"/>
            <inertia ixx="0.0952" ixy="0.00066457" ixz="0.0003989" iyy="0.5002" iyz="-0.005328" izz="0.5679"/>
            <origin xyz="0.0230654545  0.0004316655 -0.0061157216" rpy="0 0 0"/>
        </inertial>
        <collision>
            <geometry>
                <box size="0.1 0.05 0.02"/>
            </geometry>
            <origin xyz="0.05 0 -0.01" rpy="0 0 0"/>
        </collision>
    </link>
</robot>
