


<?xml version="1.0"?>
<robot name="balance">

  <material name="white">
    <color rgba="1 1 1 1"/>
  </material>

  <material name="yellow">
    <color rgba="0.8 0.8 0.2 1"/>
  </material>


  <material name="black">
    <color rgba="0.4 0.4 0.4 1"/>
  </material>

  <material name="blue">
    <color rgba="0 0 1 1"/>
  </material>

  <material name="red">
    <color rgba="0.7 0.2 0.7 1"/>
  </material>

	<link name="world">
	<inertial>
      <mass value="0"/>
      <inertia ixx="0.2125" ixy="-0.005" ixz="0.0225" iyy="0.205" iyz="0.045" izz="0.0125"/>
      <origin rpy="0 0 0" xyz="0 0 0"/>
    </inertial>
	</link>

    <link name="x_prismatic">
	 <inertial>
      <mass value="0.01"/>
      <inertia ixx="0.2125" ixy="-0.005" ixz="0.0225" iyy="0.205" iyz="0.045" izz="0.0125"/>
      <origin rpy="0 0 0" xyz="0 0 0"/>
    </inertial>
	</link>

	<joint name="x_to_world" type="prismatic">
    <parent link="world"/>
    <child link="x_prismatic"/>
    <axis xyz="1 0 0"/>
    <limit effort="0.0" lower="1" upper="-1" velocity="1000.0"/>
    <origin rpy="0 0 0" xyz="0 0 0"/>
  </joint>


	<link name="y_prismatic">
	 <inertial>
      <mass value="0.01"/>
      <inertia ixx="0.2125" ixy="-0.005" ixz="0.0225" iyy="0.205" iyz="0.045" izz="0.0125"/>
      <origin rpy="0 0 0" xyz="0 0 0"/>
    </inertial>
	</link>

	<joint name="y_to_x" type="prismatic">
    <parent link="x_prismatic"/>
    <child link="y_prismatic"/>
    <axis xyz="0 1 0"/>
    <limit effort="0.0" lower="1" upper="-1" velocity="1000.0"/>
    <origin rpy="0 0 0" xyz="0 0 0"/>
  </joint>

	<link name="z_prismatic">
	 <inertial>
      <mass value="0.01"/>
      <inertia ixx="0.2125" ixy="-0.005" ixz="0.0225" iyy="0.205" iyz="0.045" izz="0.0125"/>
      <origin rpy="0 0 0" xyz="0 0 0"/>
    </inertial>
	</link>

	<joint name="z_to_y" type="prismatic">
    <parent link="y_prismatic"/>
    <child link="z_prismatic"/>
    <axis xyz="0 0 1"/>
     <limit effort="0.0" lower="1" upper="-1" velocity="1000.0"/>
    <origin rpy="0 0 0" xyz="0 0 0"/>
  </joint>

	<joint name="torso_to_z" type="continuous">
    <parent link="z_prismatic"/>
    <child link="torso"/>
    <axis xyz="1 0 0"/>
    <origin rpy="0 0 0" xyz="0 0 0"/>
  </joint>

  <link name="torso">
    <visual>
      <geometry>
        <box size="0.2 0.1 0.48"/>
      </geometry>
      <origin rpy="0 0 0" xyz="0 0.0 0"/>
      <material name="yellow"/>
    </visual>
    <collision>
      <geometry>
        <box size="0.2 0.1 0.48"/>
      </geometry>
      <origin rpy="0 0 0" xyz="0 0.0 0"/>
      <contact_coefficients mu="0.08" />
    </collision>
    <inertial>
      <mass value="10.14"/>
      <inertia ixx="190" ixy="-0.237" ixz="2.20" iyy="194" iyz="1.42" izz="30.8"/>
      <origin rpy="0 0 0" xyz="0.00672 0.00244 0.226"/>
    </inertial>
  </link>

  <link name="r_upperleg">
    <visual>
      <geometry>
        <box size="0.05 0.1 .45"/>
      </geometry>
      <origin rpy="0 0 0" xyz="0.018 0. -0.225"/>
      <material name="black"/>
    </visual>
    <collision>
      <geometry>
        <box size="0.05 0.1 .45"/>
      </geometry>
      <origin rpy="0 0 0" xyz="0.018 -0.0 -0.225"/>
      <contact_coefficients mu="0.08" />
    </collision>
    <inertial>
      <mass value="1.59"/>
      <inertia ixx="10.4" ixy="-0.00195" ixz="0.0231" iyy="9.33" iyz="-0.127" izz="1.61"/>
      <origin rpy="0 0 0" xyz="0.0154 -0.00421 -0.111"/>
    </inertial>
  </link>


  <joint name="torso_to_rightleg" type="revolute">
    <parent link="torso"/>
    <child link="r_upperleg"/>
    <axis xyz="1 0 0"/>
    <limit effort="1000.0" lower="-1.77." upper="1.77" velocity="1000.0"/>
    <origin rpy="0 0 0" xyz="0.1 0 -0.24"/>
  </joint>

  <link name="l_upperleg">
    <visual>
      <geometry>
        <box size="0.05 0.1 .45"/>
      </geometry>
      <origin rpy="0 0 0" xyz="-0.018 0. -0.225"/>
      <material name="black"/>
    </visual>
    <collision>
      <geometry>
        <box size="0.05 0.1 .45"/>
      </geometry>
      <origin rpy="0 0 0" xyz="-0.018 0.0 -0.225"/>
      <contact_coefficients mu="0.08" />
    </collision>
    <inertial>
      <mass value="1.59"/>
      <inertia ixx="10.4" ixy="0.00286" ixz="0.0266" iyy="9.33" iyz="0.325" izz="1.65"/>
      <origin rpy="0 0 0" xyz="-0.00167 0.00371 -0.111"/>
    </inertial>
  </link>


  <joint name="torso_to_leftleg" type="revolute">
    <parent link="torso"/>
    <child link="l_upperleg"/>
    <axis xyz="1 0 0"/>
    <limit effort="1000.0" lower="-1.77." upper="1.77" velocity="1000.0"/>
    <origin rpy="0 0 0" xyz="-0.1 0 -0.24"/>
  </joint>

  <link name="r_lowerleg">
    <visual>
      <geometry>
        <box size="0.05 0.05 .45"/>
      </geometry>
      <origin rpy="0 0 0" xyz="0.0 0. -0.225"/>
      <material name="blue"/>
    </visual>
    <collision>
      <geometry>
        <box size="0.05 0.05 .45"/>
      </geometry>
      <origin rpy="0 0 0" xyz="0.0 0.0 -0.225"/>
      <contact_coefficients mu="0.08" />
    </collision>
    <inertial>
      <mass value="0.267"/>
      <inertia ixx="2.52" ixy="-0.000411" ixz="-0.0238" iyy="2.45" iyz="0.0366" izz="0.0110"/>
      <origin rpy="0 0 0" xyz="0.00153 0.00496 -0.105"/>
    </inertial>
  </link>


  <joint name="r_knee" type="revolute">
    <parent link="r_upperleg"/>
    <child link="r_lowerleg"/>
    <axis xyz="1 0 0"/>
    <limit effort="10.0" lower="-1.97." upper="0.1" velocity="1000.0"/>
    <origin rpy="0 0 0" xyz="0.015 0 -.45"/>
  </joint>

  <link name="l_lowerleg">
    <visual>
      <geometry>
        <box size="0.05 0.05 .45"/>
      </geometry>
      <origin rpy="0 0 0" xyz="-0.0 0. -0.225"/>
      <material name="blue"/>
    </visual>
    <collision>
      <geometry>
        <box size="0.05 0.05 .45"/>
      </geometry>
      <origin rpy="0 0 0" xyz="-0.0 0.0 -0.225"/>
      <contact_coefficients mu="0.08" />
    </collision>
    <inertial>
      <mass value="0.267"/>
      <inertia ixx="2.52" ixy="-0.000411" ixz="-0.0238" iyy="2.45" iyz="0.0366" izz="0.0110"/>
      <origin rpy="0 0 0" xyz="0.00153 0.00496 -0.105"/>
    </inertial>
  </link>


  <joint name="l_knee" type="revolute">
    <parent link="l_upperleg"/>
    <child link="l_lowerleg"/>
    <axis xyz="1 0 0"/>
    <limit effort="10.0" lower="-1.97." upper="0.1" velocity="1000.0"/>
    <origin rpy="0 0 0" xyz="-0.015 0 -.45"/>
  </joint>

  <link name="l_foot">
    <visual>
      <geometry>
        <box size="0.06 0.185 .04"/>
      </geometry>
      <origin rpy="0 0 0" xyz="0.0 0.09 -0.03"/>
      <material name="red"/>
    </visual>
    <collision>
      <geometry>
        <box size="0.06 0.185 .04"/>
      </geometry>
      <origin rpy="0 0 0" xyz="0.0 0.09 -0.03"/>
      <contact_coefficients mu="0.65" />
    </collision>
    <inertial>
      <mass value="0.2356"/>
      <inertia ixx="0.0952" iyy="0.5002" izz="0.5679" ixy="0.00066457" ixz="0.0003989" iyz="-0.005328"/>
      <origin rpy="0 0 0" xyz="0.0230654545 0.0004316655 -0.0061157216"/>
    </inertial>
  </link>

  <joint name="l_ankle" type="revolute">
    <parent link="l_lowerleg"/>
    <child link="l_foot"/>
    <axis xyz="1 0 0"/>
    <limit effort="10.0" lower="-2" upper="2" velocity="1000.0"/>
    <origin rpy="0 0 0" xyz="-0.0 -0.035 -.45"/>
  </joint>


  <link name="r_foot">
    <visual>
      <geometry>
        <box size="0.06 0.185 .04"/>
      </geometry>
      <origin rpy="0 0 0" xyz="-0.0 0.09 -0.03"/>
      <material name="red"/>
    </visual>
    <collision>
      <geometry>
        <box size="0.06 0.185 .04"/>
      </geometry>
      <origin rpy="0 0 0" xyz="-0.0 0.09 -0.03"/>
      <contact_coefficients mu="0.65" />
    </collision>
    <inertial>
      <mass value="0.2356"/>
      <inertia ixx="0.0952" iyy="0.5002" izz="0.5679" ixy="0.00066457" ixz="0.0003989" iyz="-0.005328"/>
      <origin rpy="0 0 0" xyz="0.0230654545 0.0004316655 -0.0061157216"/>
    </inertial>
  </link>

  <joint name="r_ankle" type="revolute">
    <parent link="r_lowerleg"/>
    <child link="r_foot"/>
    <axis xyz="1 0 0"/>
    <limit effort="10.0" lower="-2." upper="2" velocity="1000.0"/>
    <origin rpy="0 0 0" xyz="0.0 -0.035 -.45"/>
  </joint>

</robot>
