<?xml version="1.0" ?>
<robot name="humanoid">

	<link name="world">
	<inertial>
      <mass value="0"/>
      <inertia ixx="0.2125" ixy="-0.005" ixz="0.0225" iyy="0.205" iyz="0.045" izz="0.0125"/>
      <origin rpy="0 0 0" xyz="0 0 0"/>
    </inertial>
	</link>

	<link name="x_prismatic">
	 <inertial>
      <mass value="0.01"/>
      <inertia ixx="0.2125" ixy="-0.005" ixz="0.0225" iyy="0.205" iyz="0.045" izz="0.0125"/>
      <origin rpy="0 0 0" xyz="0 0 0"/>
    </inertial>
	</link>

	<joint name="x_to_world" type="prismatic">
    <parent link="world"/>
    <child link="x_prismatic"/>
    <axis xyz="1 0 0"/>
    <limit effort="0.0" lower="10" upper="-10" velocity="1000.0"/>
    <origin rpy="0 0 0" xyz="0 0 0"/>
  </joint>

	<link name="z_prismatic">
	 <inertial>
      <mass value="0.01"/>
      <inertia ixx="0.2125" ixy="-0.005" ixz="0.0225" iyy="0.205" iyz="0.045" izz="0.0125"/>
      <origin rpy="0 0 0" xyz="0 0 0"/>
    </inertial>
	</link>

	<joint name="z_to_y" type="prismatic">
    <parent link="x_prismatic"/>
    <child link="z_prismatic"/>
    <axis xyz="0 0 1"/>
     <limit effort="0.0" lower="10" upper="-10" velocity="1000.0"/>
    <origin rpy="0 0 0" xyz="0 0 0"/>
  </joint>

	<joint name="torso_to_z" type="revolute">
    <parent link="z_prismatic"/>
    <child link="body"/>
    <axis xyz="0 1 0"/>
    <origin rpy="0 0 0" xyz="0 0 0"/>
    <limit effort="0.0" lower="10" upper="-10" velocity="1000.0"/>
  </joint>


    <link name="body">
        <visual>
            <geometry>
                <box size="0.05 0.2 0.3"/>
            </geometry>
            <origin xyz="0.0 0 0.0" rpy="0 0 0"/>
            <material name="linkColor">
                <color rgba="1 1 1 1"/>
            </material>
        </visual>
        <inertial>
            <mass value="5.81"/>
            <inertia ixx="0.190" ixy="-0.000237" ixz="0.00220" iyy="0.194" iyz="0.00142" izz="0.0308"/>
            <origin xyz="0.00672  0.00244 0.076" rpy="0 0 0"/>
        </inertial>
        <collision>
            <geometry>
                <box size="0.05 0.2 0.3"/>
            </geometry>
            <origin xyz="0.0 0 0.0" rpy="0 0 0"/>
        </collision>
    </link>

    <!-- ****************************Right leg joints******************************************** -->

    <joint name="jointHipR" type="revolute">
        <parent link="body"/>
        <child link="hipCylinderR"/>
        <origin xyz="0 0.0 -0.15" rpy="0 0 0"/>
        <axis xyz="1 0 0"/>
        <limit effort="90" lower="-0.174533" upper="0" velocity="10"/>
        <dynamics damping="0.01"/>
    </joint>


    <link name="hipCylinderR">
        <visual>
            <geometry>
                <cylinder length="0.04" radius="0.01"/>
            </geometry>
            <origin xyz="0 0 0.0" rpy="0 1.57 0"/>
            <axis xyz="0 0 0" />
            <material name="red">
                <color rgba="1 0.0 0.0 1.0"/>
            </material>
        </visual>
        <inertial>
            <mass value="0"/>
            <inertia ixx="0" ixy="0" ixz="0.0" iyy="0" iyz="0.0" izz="0"/>
        </inertial>
    </link>

    <joint name="jointUpperLegR" type="revolute">
        <parent link="hipCylinderR"/>
        <child link="upperLegCylinderR"/>
        <origin xyz="0 -0.0830 -0.0250" rpy="0 0 0"/>
        <axis xyz="0 1 0"/>
        <limit effort="90" lower="-1.047" upper="+0.698132" velocity="10"/>
        <dynamics damping="0.173402366366"/>
    </joint>

    <link name="upperLegCylinderR">
        <visual>
            <geometry>
                <cylinder length="0.04" radius="0.01"/>
            </geometry>
            <origin xyz="0 0 0" rpy="1.57 0 0"/>
            <axis xyz="0 0 0" />
            <material name="red"/>
        </visual>
        <inertial>
            <mass value="0"/>
            <inertia ixx="0" ixy="0" ixz="0.0" iyy="0" iyz="0.0" izz="0"/>
        </inertial>
    </link>

    <joint name="jointLowerLegR" type="revolute">
        <parent link="upperLegCylinderR"/>
        <child link="lowerlegCylinderR"/>
        <origin xyz="0.00110 0.0140 -0.3155" rpy="0 0 0"/>
        <axis xyz="0 1 0"/>
        <limit effort="90" lower="0" upper="1.570796" velocity="10"/>
        <dynamics damping="0.198431592389"/>
    </joint>

    <link name="lowerlegCylinderR">
        <visual>
            <geometry>
                <cylinder length="0.044" radius="0.01"/>
            </geometry>
            <origin xyz="0 0 0" rpy="1.57075 0 0"/>
            <axis xyz="0 0 0" />
            <material name="red"/>
        </visual>
        <inertial>
            <mass value="0"/>
            <inertia ixx="0" ixy="0" ixz="0.0" iyy="0" iyz="0.0" izz="0"/>
        </inertial>
    </link>

    <joint name="jointAnkleR" type="revolute">
        <parent link="lowerlegCylinderR"/>
        <child link="ankleCylinderR"/>
        <origin xyz="0.00300 0 -0.2915" rpy="0 0 0"/>
        <axis xyz="0 1 0"/>
        <limit effort="90" lower="-0.436332" upper="+0.436332" velocity="10"/>
        <dynamics damping="0.0005"/>
    </joint>

    <link name="ankleCylinderR">
        <visual>
            <geometry>
                <cylinder length="0.04" radius="0.01"/>
            </geometry>
            <origin xyz="0 0 0" rpy="1.57075 0 0"/>
            <axis xyz="0 0 0" />
            <material name="red"/>
        </visual>
        <inertial>
            <mass value="0"/>
            <inertia ixx="0" ixy="0" ixz="0.0" iyy="0" iyz="0.0" izz="0"/>
        </inertial>
    </link>
<!--
    <joint name="jointfootR" type="revolute">
        <parent link="ankleCylinderR"/>
        <child link="footCylinderR"/>
        <origin xyz="0 0 -0.0115" rpy="0 0 0"/>
        <axis xyz="1 0 0"/>
        <limit effort="10" lower="-3" upper="+3" velocity="10"/>
        <dynamics damping="0"/>
    </joint>
    <link name="footCylinderR">
        <visual>
            <geometry>
                <cylinder length="0.04" radius="0.01"/>
            </geometry>
            <origin xyz="0 0 0.02" rpy="0 1.57 0"/>
            <axis xyz="0 0 0" />
            <material name="red"/>
        </visual>
        <inertial>
            <mass value="0"/>
            <inertia ixx="0" ixy="0" ixz="0.0" iyy="0" iyz="0.0" izz="0"/>
        </inertial>
    </link> -->

    <!--************************************ Left leg joints **********************************************-->


    <joint name="jointHipL" type="revolute">
        <parent link="body"/>
        <child link="hipCylinderL"/>
        <origin xyz="0 0.0 -0.15" rpy="0 0 0"/>
        <axis xyz="1 0 0"/>
        <limit effort="90" lower="0" upper="+0.174533" velocity="10"/>
        <dynamics damping="0.01"/>
    </joint>


    <link name="hipCylinderL">
        <visual>
            <geometry>
                <cylinder length="0.04" radius="0.01"/>
            </geometry>
            <origin xyz="0 0 0" rpy="0 1.57 0"/>
            <axis xyz="0 0 0" />
            <material name="red">
                <color rgba="1 0.0 0.0 1.0"/>
            </material>
        </visual>
        <inertial>
            <mass value="0"/>
            <inertia ixx="0" ixy="0" ixz="0.0" iyy="0" iyz="0.0" izz="0"/>
        </inertial>
    </link>

    <joint name="jointUpperLegL" type="revolute">
        <parent link="hipCylinderL"/>
        <child link="upperLegCylinderL"/>
        <origin xyz="0 0.0830 -0.0250" rpy="0 -0.5 0"/>
        <axis xyz="0 1 0"/>
        <limit effort="10" lower="-0.523599" upper="+1.22173" velocity="10"/>
        <dynamics damping="0.173402366366"/>
    </joint>

    <link name="upperLegCylinderL">
        <visual>
            <geometry>
                <cylinder length="0.04" radius="0.01"/>
            </geometry>
            <origin xyz="0 0 0.0" rpy="1.57 0 0"/>
            <axis xyz="0 0 0" />
            <material name="red"/>
        </visual>
        <inertial>
            <mass value="0"/>
            <inertia ixx="0" ixy="0" ixz="0.0" iyy="0" iyz="0.0" izz="0"/>
        </inertial>
    </link>

    <joint name="jointLowerLegL" type="revolute">
        <parent link="upperLegCylinderL"/>
        <child link="lowerlegCylinderL"/>
        <origin xyz="0.00110 -0.0140 -0.3155" rpy="0 0 0"/>
        <axis xyz="0 1 0"/>
        <limit effort="90" lower="0" upper="1.570796" velocity="10"/>
        <dynamics damping="0.198431592389"/>
    </joint>

    <link name="lowerlegCylinderL">
        <visual>
            <geometry>
                <cylinder length="0.04" radius="0.01"/>
            </geometry>
            <origin xyz="0 0 0" rpy="1.57075 0 0"/>
            <axis xyz="0 0 0" />
            <material name="red"/>
        </visual>
        <inertial>
            <mass value="0"/>
            <inertia ixx="0" ixy="0" ixz="0.0" iyy="0" iyz="0.0" izz="0"/>
        </inertial>
    </link>

    <joint name="jointAnkleL" type="revolute">
        <parent link="lowerlegCylinderL"/>
        <child link="ankleCylinderL"/>
        <origin xyz="0.00300 0 -0.2915" rpy="0 0 0"/>
        <axis xyz="0 1 0"/>
        <limit effort="90" lower="-0.436332" upper="+0.436332" velocity="10"/>
        <dynamics damping="0.0005"/>
    </joint>

    <link name="ankleCylinderL">
        <visual>
            <geometry>
                <cylinder length="0.04" radius="0.01"/>
            </geometry>
            <origin xyz="0 0 0" rpy="1.57075 0 0"/>
            <axis xyz="0 0 0" />
            <material name="red"/>
        </visual>
        <inertial>
            <mass value="0"/>
            <inertia ixx="0" ixy="0" ixz="0.0" iyy="0" iyz="0.0" izz="0"/>
        </inertial>
    </link>

    <!-- <joint name="jointfootL" type="revolute">
        <parent link="ankleCylinderL"/>
        <child link="footCylinderL"/>
        <origin xyz="0 0 -0.0115" rpy="0 0 0"/>
        <axis xyz="1 0 0"/>
        <limit effort="10" lower="-3" upper="+3" velocity="10"/>
        <dynamics damping="0"/>
    </joint>
    <link name="footCylinderL">
        <visual>
            <geometry>
                <cylinder length="0.04" radius="0.01"/>
            </geometry>
            <origin xyz="0 0 0.02" rpy="0 1.57 0"/>
            <axis xyz="0 0 0" />
            <material name="red"/>
        </visual>
        <inertial>
            <mass value="0"/>
            <inertia ixx="0" ixy="0" ixz="0.0" iyy="0" iyz="0.0" izz="0"/>
        </inertial>
    </link> -->

    <!-- **************************************Decorations Right leg **********************************************-->


    <joint name="fixed_hipBridgeR" type="fixed">
        <parent link="hipCylinderR"/>
        <child link="hipBridgeR"/>
    </joint>

    <link name="hipBridgeR">
        <visual>
            <geometry>
                <box size="0.02 0.0830 0.0250"/>
            </geometry>
            <origin xyz="0 -0.0415 0.0" rpy="0 0 0"/>
            <material name="linkColor">
                <color rgba="1 1 1 1"/>
            </material>
        </visual>
        <inertial>
            <mass value="0.219"/>
            <inertia ixx="0.000414" ixy="0.0000149" ixz="0.00000188" iyy="0.000128" iyz="-0.0000311" izz="0.000395"/>
            <origin rpy="0 0 0" xyz="0.00131 -0.0515 -0.00661"/>
        </inertial>
        <collision>
            <geometry>
                <box size="0.02 0.0830 0.0250"/>
            </geometry>
            <origin xyz="0 -0.0415 0.0" rpy="0 0 0"/>
            <!-- <contact_coefficient mu="0.0"  resitution="0"  k_p="4000"  k_d="0.01" /> -->
        </collision>
    </link>

    <joint name="fixed_upperLegBridgeR" type="fixed">
        <parent link="upperLegCylinderR"/>
        <child link="upperLegBridgeR"/>
    </joint>

    <link name="upperLegBridgeR">
        <visual>
            <geometry>
                <box size="0.1 0.05 0.32"/>
            </geometry>
            <origin xyz="0.0 0.0 -0.16" rpy="0 0 0"/>
            <material name="linkColor">
                <color rgba="1 1 1 1"/>
            </material>
        </visual>
        <inertial>
            <mass value="1.94"/>
            <inertia ixx="0.0104" ixy="-0.00000195" ixz="0.0000231" iyy="0.00933" iyz="-0.000127" izz="0.00161"/>
            <origin xyz="0.00154  -0.00421 -0.111" rpy="0 0 0"/>
        </inertial>
        <collision>
            <geometry>
                <box size="0.1 0.05 0.32"/>
            </geometry>
            <origin xyz="0.0 0.0 -0.16" rpy="0 0 0"/>
            <!-- <contact_coefficient mu="0.0578491069103"  resitution="0"  k_p="4000"  k_d="0.173402366366" /> -->
        </collision>
    </link>

    <joint name="fixed_lowerLegBridgeR" type="fixed">
        <parent link="lowerlegCylinderR"/>
        <child link="lowerLegBridgeR"/>
    </joint>

    <link name="lowerLegBridgeR">
        <visual>
            <geometry>
                <box size="0.05 0.05 0.28"/>
            </geometry>
            <origin xyz="0 0 -0.14" rpy="0 0 0"/>
            <material name="linkColor">
                <color rgba="1 1 1 1"/>
            </material>
        </visual>
        <inertial>
            <mass value="0.267"/>
            <inertia ixx="0.00252" ixy="-0.000000411" ixz="-0.0000238" iyy="0.00245" iyz="0.0000366" izz="0.000110"/>
            <origin xyz="0.00153  0.00496 -0.105" rpy="0 0 0"/>
        </inertial>
        <collision>
            <geometry>
                <box size="0.05 0.05 0.28"/>
            </geometry>
            <origin xyz="0.0 0 -0.14" rpy="0 0 0"/>
            <!-- <contact_coefficient mu="0.0960723602789"  resitution="0"  k_p="4000"  k_d="0.198431592389" /> -->
        </collision>
    </link>


    <joint name="fixed_ankleBridgeR" type="fixed">
        <parent link="ankleCylinderR"/>
        <child link="ankleBridgeR"/>
    </joint>

    <link name="ankleBridgeR">
        <visual>
            <geometry>
                <box size="0.16 0.13 0.02"/>
            </geometry>
            <origin xyz="0.04 0 -0.01" rpy="0 0 0"/>
            <material name="linkColor">
                <color rgba="1 1 1 1"/>
            </material>
        </visual>
        <inertial>
            <mass value="0.2356"/>
            <inertia ixx="0.0000952" ixy="0.00000066457" ixz="0.0000003989" iyy="0.0005002" iyz="-0.000005328" izz="0.0005679"/>
            <origin xyz="0.0230654545  0.0004316655 -0.0061157216" rpy="0 0 0"/>
        </inertial>
        <collision>
            <geometry>
                <box size="0.16 0.13 0.02"/>
            </geometry>
            <origin xyz="0.04 0 -0.01" rpy="0 0 0"/>
            <contact_coefficient mu="0.5"  resitution="0"  k_p="0"  k_d="0.0005" />
        </collision>
    </link>

    <!--&lt;!&ndash; *********************************Decorations Left leg ******************************************&ndash;&gt;-->
    <joint name="fixed_hipBridgeL" type="fixed">
        <parent link="hipCylinderL"/>
        <child link="hipBridgeL"/>
    </joint>

    <link name="hipBridgeL">
        <visual>
            <geometry>
                <box size="0.02 0.0830 0.0250"/>
            </geometry>
            <origin xyz="0 0.0415 0" rpy="0 0 0"/>
            <material name="linkColor">
                <color rgba="1 1 1 1"/>
            </material>
        </visual>
        <inertial>
            <mass value="0.219"/>
            <inertia ixx="0.000414" ixy="0.0000149" ixz="-0.00000188" iyy="0.000128" iyz="0.0000311" izz="0.000359"/>
            <origin rpy="0 0 0" xyz="-0.00131 0.0515 -0.00661"/>
        </inertial>
        <collision>
            <geometry>
                <box size="0.02 0.0830 0.0250"/>
            </geometry>
            <origin xyz="0 0.0415 0.0125" rpy="0 0 0"/>
            <!-- <contact_coefficient mu="0.0"  resitution="0"  k_p="4000"  k_d="0.01" /> -->
        </collision>
    </link>

    <joint name="fixed_upperLegBridgeL" type="fixed">
        <parent link="upperLegCylinderL"/>
        <child link="upperLegBridgeL"/>
    </joint>

    <link name="upperLegBridgeL">
        <visual>
            <geometry>
                <box size="0.1 0.05 0.32"/>
            </geometry>
            <origin xyz="0 0 -0.16" rpy="0 0 0"/>
            <material name="linkColor">
                <color rgba="1 1 1 1"/>
            </material>
        </visual>
        <inertial>
            <mass value="1.94"/>
            <inertia ixx="0.0104" ixy="0.00000286" ixz="0.0000226" iyy="0.00933" iyz="0.000325" izz="0.00165"/>
            <origin xyz="-0.00167  0.00371 -0.111" rpy="0 0 0"/>
        </inertial>
        <collision>
            <geometry>
                <box size="0.1 0.05 0.32"/>
            </geometry>
            <origin xyz="0 0 -0.16" rpy="0 0 0"/>
            <!-- <contact_coefficient mu="0.0578491069103"  resitution="0"  k_p="4000"  k_d="0.173402366366" /> -->
        </collision>
    </link>

    <joint name="fixed_lowerLegBridgeL" type="fixed">
        <parent link="lowerlegCylinderL"/>
        <child link="lowerLegBridgeL"/>
    </joint>

    <link name="lowerLegBridgeL">
        <visual>
            <geometry>
                <box size="0.05 0.05 0.28"/>
            </geometry>
            <origin xyz="0 0 -0.14" rpy="0 0 0"/>
            <material name="linkColor">
                <color rgba="1 1 1 1"/>
            </material>
        </visual>
        <inertial>
            <mass value="0.267"/>
            <inertia ixx="0.00252" ixy="-0.000000411" ixz="-0.0000238" iyy="0.00245" iyz="0.0000366" izz="0.000110"/>
            <origin xyz="0.00153  0.00496 -0.105" rpy="0 0 0"/>
        </inertial>
        <collision>
            <geometry>
                <box size="0.05 0.05 0.28"/>
            </geometry>
            <origin xyz="0 0 -0.14" rpy="0 0 0"/>
            <!-- <contact_coefficient mu="0.0960723602789"  resitution="0"  k_p="4000"  k_d="0.198431592389" /> -->
        </collision>
    </link>


    <joint name="fixed_ankleBridgeL" type="fixed">
        <parent link="ankleCylinderL"/>
        <child link="ankleBridgeL"/>
    </joint>

    <link name="ankleBridgeL">
        <visual>
            <geometry>
                <box size="0.16 0.13 0.02"/>
            </geometry>
            <origin xyz="0.04 0 -0.01" rpy="0 0 0"/>
            <material name="linkColor">
                <color rgba="1 1 1 1"/>
            </material>
        </visual>
        <inertial>
            <mass value="0.2356"/>
            <inertia ixx="0.0000952" ixy="0.00000066457" ixz="0.0000003989" iyy="0.0005002" iyz="-0.000005328" izz="0.0005679"/>
            <origin xyz="0.0230654545  0.0004316655 -0.0061157216" rpy="0 0 0"/>
        </inertial>
        <collision>
            <geometry>
                <box size="0.16 0.13 0.02"/>
            </geometry>
            <origin xyz="0.04 0 -0.01" rpy="0 0 0"/>
            <contact_coefficient mu="0.5"  resitution="0"  k_p="0"  k_d="0.0005" />
        </collision>
    </link>

</robot>